import exception_classname

a = exception_classname.Exception()
assert a.testfunc() == 42
